Failure # 1 (occurred at 2021-05-14_03-51-34)
Traceback (most recent call last):
  File "/home/ych/anaconda3/envs/DeepCrypto/lib/python3.7/site-packages/ray/tune/trial_runner.py", line 702, in _process_trial
    results = self.trial_executor.fetch_result(trial)
  File "/home/ych/anaconda3/envs/DeepCrypto/lib/python3.7/site-packages/ray/tune/ray_trial_executor.py", line 686, in fetch_result
    result = ray.get(trial_future[0], timeout=DEFAULT_GET_TIMEOUT)
  File "/home/ych/anaconda3/envs/DeepCrypto/lib/python3.7/site-packages/ray/_private/client_mode_hook.py", line 47, in wrapper
    return func(*args, **kwargs)
  File "/home/ych/anaconda3/envs/DeepCrypto/lib/python3.7/site-packages/ray/worker.py", line 1481, in get
    raise value.as_instanceof_cause()
ray.exceptions.RayTaskError(TuneError): [36mray::ImplicitFunc.train_buffered()[39m (pid=50879, ip=192.168.68.106)
  File "python/ray/_raylet.pyx", line 505, in ray._raylet.execute_task
  File "python/ray/_raylet.pyx", line 449, in ray._raylet.execute_task.function_executor
  File "/home/ych/anaconda3/envs/DeepCrypto/lib/python3.7/site-packages/ray/_private/function_manager.py", line 556, in actor_method_executor
    return method(__ray_actor, *args, **kwargs)
  File "/home/ych/anaconda3/envs/DeepCrypto/lib/python3.7/site-packages/ray/tune/trainable.py", line 173, in train_buffered
    result = self.train()
  File "/home/ych/anaconda3/envs/DeepCrypto/lib/python3.7/site-packages/ray/tune/trainable.py", line 232, in train
    result = self.step()
  File "/home/ych/anaconda3/envs/DeepCrypto/lib/python3.7/site-packages/ray/tune/function_runner.py", line 366, in step
    self._report_thread_runner_error(block=True)
  File "/home/ych/anaconda3/envs/DeepCrypto/lib/python3.7/site-packages/ray/tune/function_runner.py", line 513, in _report_thread_runner_error
    ("Trial raised an exception. Traceback:\n{}".format(err_tb_str)
ray.tune.error.TuneError: Trial raised an exception. Traceback:
[36mray::ImplicitFunc.train_buffered()[39m (pid=50879, ip=192.168.68.106)
  File "/home/ych/anaconda3/envs/DeepCrypto/lib/python3.7/site-packages/ray/tune/function_runner.py", line 248, in run
    self._entrypoint()
  File "/home/ych/anaconda3/envs/DeepCrypto/lib/python3.7/site-packages/ray/tune/function_runner.py", line 316, in entrypoint
    self._status_reporter.get_checkpoint())
  File "/home/ych/anaconda3/envs/DeepCrypto/lib/python3.7/site-packages/ray/tune/function_runner.py", line 580, in _trainable_func
    output = fn()
  File "/home/ych/anaconda3/envs/DeepCrypto/lib/python3.7/site-packages/ray/tune/utils/trainable.py", line 339, in _inner
    inner(config, checkpoint_dir=None)
  File "/home/ych/anaconda3/envs/DeepCrypto/lib/python3.7/site-packages/ray/tune/utils/trainable.py", line 330, in inner
    trainable(config, **fn_kwargs)
  File "<ipython-input-9-39a6bf5db46a>", line 3, in optimizer
  File "<ipython-input-3-67f57e02ff0c>", line 2, in strategy
KeyError: 'volume'

